<?xml version="1.0" encoding="UTF-8"?><testrun name="NovelExceptionsTest" project="backend" tests="5" started="5" failures="1" errors="0" ignored="0">
  <testsuite name="com.novelsbr.backend.exceptions.NovelExceptionsTest" time="50.294" displayname="NovelExceptionsTest" uniqueid="[engine:junit-jupiter]/[class:com.novelsbr.backend.exceptions.NovelExceptionsTest]">
    <testcase name="setUp" classname="com.novelsbr.backend.exceptions.NovelExceptionsTest" time="49.93" displayname="setUp()" uniqueid="[engine:junit-jupiter]/[class:com.novelsbr.backend.exceptions.NovelExceptionsTest]/[method:setUp()]"/>
    <testcase name="nullEntityException" classname="com.novelsbr.backend.exceptions.NovelExceptionsTest" time="0.305" displayname="nullEntityException()" uniqueid="[engine:junit-jupiter]/[class:com.novelsbr.backend.exceptions.NovelExceptionsTest]/[method:nullEntityException()]">
      <failure>
        <expected>class com.novelsbr.backend.exceptions.NullEntityException</expected>
        <actual>class java.lang.NullPointerException</actual>
        org.opentest4j.AssertionFailedError: Unexpected exception type thrown, expected: &lt;com.novelsbr.backend.exceptions.NullEntityException&gt; but was: &lt;java.lang.NullPointerException&gt;&#13;
	at org.junit.jupiter.api.AssertionFailureBuilder.build(AssertionFailureBuilder.java:151)&#13;
	at org.junit.jupiter.api.AssertThrows.assertThrows(AssertThrows.java:67)&#13;
	at org.junit.jupiter.api.AssertThrows.assertThrows(AssertThrows.java:35)&#13;
	at org.junit.jupiter.api.Assertions.assertThrows(Assertions.java:3128)&#13;
	at com.novelsbr.backend.exceptions.NovelExceptionsTest.nullEntityException(NovelExceptionsTest.java:109)&#13;
	at java.base/java.lang.reflect.Method.invoke(Method.java:568)&#13;
	at java.base/java.util.ArrayList.forEach(ArrayList.java:1511)&#13;
	at java.base/java.util.ArrayList.forEach(ArrayList.java:1511)&#13;
Caused by: java.lang.NullPointerException: Cannot invoke "com.novelsbr.backend.domain.entities.Novel.getId()" because "novel" is null&#13;
	at com.novelsbr.backend.domain.dto.NovelDTO.&lt;init&gt;(NovelDTO.java:34)&#13;
	at com.novelsbr.backend.exceptions.NovelExceptionsTest.lambda$3(NovelExceptionsTest.java:109)&#13;
	at org.junit.jupiter.api.AssertThrows.assertThrows(AssertThrows.java:53)&#13;
	... 6 more&#13;
&#13;

      </failure>
    </testcase>
    <testcase name="existingNovelException" classname="com.novelsbr.backend.exceptions.NovelExceptionsTest" time="0.006" displayname="existingNovelException()" uniqueid="[engine:junit-jupiter]/[class:com.novelsbr.backend.exceptions.NovelExceptionsTest]/[method:existingNovelException()]"/>
    <testcase name="entityNotFoundException01" classname="com.novelsbr.backend.exceptions.NovelExceptionsTest" time="0.016" displayname="entityNotFoundException01()" uniqueid="[engine:junit-jupiter]/[class:com.novelsbr.backend.exceptions.NovelExceptionsTest]/[method:entityNotFoundException01()]"/>
    <testcase name="entityNotFoundException02" classname="com.novelsbr.backend.exceptions.NovelExceptionsTest" time="0.031" displayname="entityNotFoundException02()" uniqueid="[engine:junit-jupiter]/[class:com.novelsbr.backend.exceptions.NovelExceptionsTest]/[method:entityNotFoundException02()]"/>
  </testsuite>
</testrun>
